2020-04-09 12:45:04,444 server.py [line:45] INFO loading config file...
2020-04-09 13:26:08,910 server.py [line:46] INFO loading config file...
2020-04-09 13:26:37,757 server.py [line:48] INFO loading config file...
2020-04-09 13:28:40,948 server.py [line:48] INFO loading config file...
2020-04-09 13:29:50,360 server.py [line:47] INFO loading config file...
2020-04-09 13:30:03,398 server.py [line:47] INFO loading config file...
2020-04-09 13:30:24,476 server.py [line:47] INFO loading config file...
2020-04-09 13:30:28,377 server.py [line:47] INFO loading config file...
2020-04-09 13:30:51,638 server.py [line:48] INFO loading config file...
2020-04-09 13:32:17,545 server.py [line:48] INFO loading config file...
2020-04-09 13:33:43,628 server.py [line:47] INFO loading config file...
2020-04-09 13:33:57,090 server.py [line:47] INFO loading config file...
2020-04-09 13:34:20,870 server.py [line:47] INFO loading config file...
2020-04-09 13:34:28,205 server.py [line:47] INFO loading config file...
2020-04-09 13:34:40,416 server.py [line:47] INFO loading config file...
2020-04-09 13:35:22,037 server.py [line:49] INFO loading config file...
2020-04-09 13:35:22,221 server.py [line:66] ERROR Traceback (most recent call last):
  File "/Users/brian/Desktop/FileSync2/FileSync2/server.py", line 64, in <module>
    main()
  File "/Users/brian/Desktop/FileSync2/FileSync2/server.py", line 59, in main
    server.start()
  File "/Users/brian/Desktop/FileSync2/FileSync2/server.py", line 43, in start
    data = json.loads({'docid': kc_docid})
  File "/System/Library/Frameworks/Python.framework/Versions/2.7/lib/python2.7/json/__init__.py", line 339, in loads
    return _default_decoder.decode(s)
  File "/System/Library/Frameworks/Python.framework/Versions/2.7/lib/python2.7/json/decoder.py", line 364, in decode
    obj, end = self.raw_decode(s, idx=_w(s, 0).end())
TypeError: expected string or buffer

2020-04-09 13:37:07,184 server.py [line:50] INFO loading config file...
2020-04-09 13:37:07,321 server.py [line:67] ERROR Traceback (most recent call last):
  File "/Users/brian/Desktop/FileSync2/FileSync2/server.py", line 65, in <module>
    main()
  File "/Users/brian/Desktop/FileSync2/FileSync2/server.py", line 60, in main
    server.start()
  File "/Users/brian/Desktop/FileSync2/FileSync2/server.py", line 43, in start
    data = json.loads({'docid': kc_docid})
  File "/System/Library/Frameworks/Python.framework/Versions/2.7/lib/python2.7/json/__init__.py", line 339, in loads
    return _default_decoder.decode(s)
  File "/System/Library/Frameworks/Python.framework/Versions/2.7/lib/python2.7/json/decoder.py", line 364, in decode
    obj, end = self.raw_decode(s, idx=_w(s, 0).end())
TypeError: expected string or buffer

2020-04-09 13:37:15,500 server.py [line:50] INFO loading config file...
2020-04-09 13:38:14,333 server.py [line:50] INFO loading config file...
2020-04-09 13:38:22,087 server.py [line:50] INFO loading config file...
2020-04-09 13:59:37,642 server.py [line:50] INFO loading config file...
2020-04-09 13:59:37,781 server.py [line:67] ERROR Traceback (most recent call last):
  File "/Users/brian/Desktop/FileSync2/FileSync2/server.py", line 65, in <module>
    main()
  File "/Users/brian/Desktop/FileSync2/FileSync2/server.py", line 60, in main
    server.start()
  File "/Users/brian/Desktop/FileSync2/FileSync2/server.py", line 47, in start
    print self.asclient.permissions.get_perm(docid=docid)
AttributeError: 'DirManage' object has no attribute 'get_perm'

2020-04-09 14:01:14,812 server.py [line:50] INFO loading config file...
2020-04-09 14:01:14,961 server.py [line:67] ERROR Traceback (most recent call last):
  File "/Users/brian/Desktop/FileSync2/FileSync2/server.py", line 65, in <module>
    main()
  File "/Users/brian/Desktop/FileSync2/FileSync2/server.py", line 60, in main
    server.start()
  File "/Users/brian/Desktop/FileSync2/FileSync2/server.py", line 47, in start
    print self.asclient.permissions.get_perm(docid=docid)
  File "/Users/brian/Desktop/FileSync2/FileSync2/modules/asclient/as_permissions.py", line 27, in get_perm
    return self.request(self.dir_url, params, payload)
  File "/Users/brian/Desktop/FileSync2/FileSync2/modules/asclient/api_manage.py", line 36, in request
    return self.check_resp(resp)
  File "/Users/brian/Desktop/FileSync2/FileSync2/modules/asclient/api_manage.py", line 25, in check_resp
    result = resp.json()
  File "/Library/Python/2.7/site-packages/requests/models.py", line 898, in json
    return complexjson.loads(self.text, **kwargs)
  File "/System/Library/Frameworks/Python.framework/Versions/2.7/lib/python2.7/json/__init__.py", line 339, in loads
    return _default_decoder.decode(s)
  File "/System/Library/Frameworks/Python.framework/Versions/2.7/lib/python2.7/json/decoder.py", line 364, in decode
    obj, end = self.raw_decode(s, idx=_w(s, 0).end())
  File "/System/Library/Frameworks/Python.framework/Versions/2.7/lib/python2.7/json/decoder.py", line 382, in raw_decode
    raise ValueError("No JSON object could be decoded")
ValueError: No JSON object could be decoded

2020-04-09 14:01:54,575 server.py [line:50] INFO loading config file...
2020-04-09 14:02:03,667 server.py [line:50] INFO loading config file...
2020-04-09 14:02:30,023 server.py [line:50] INFO loading config file...
2020-04-09 14:02:30,165 server.py [line:67] ERROR Traceback (most recent call last):
  File "/Users/brian/Desktop/FileSync2/FileSync2/server.py", line 65, in <module>
    main()
  File "/Users/brian/Desktop/FileSync2/FileSync2/server.py", line 60, in main
    server.start()
  File "/Users/brian/Desktop/FileSync2/FileSync2/server.py", line 47, in start
    print self.asclient.permissions.get_perm(docid=docid)
  File "/Users/brian/Desktop/FileSync2/FileSync2/modules/asclient/as_permissions.py", line 27, in get_perm
    print (self.request(self.dir_url, params, payload))
  File "/Users/brian/Desktop/FileSync2/FileSync2/modules/asclient/api_manage.py", line 36, in request
    return self.check_resp(resp)
  File "/Users/brian/Desktop/FileSync2/FileSync2/modules/asclient/api_manage.py", line 25, in check_resp
    result = resp.json()
  File "/Library/Python/2.7/site-packages/requests/models.py", line 898, in json
    return complexjson.loads(self.text, **kwargs)
  File "/System/Library/Frameworks/Python.framework/Versions/2.7/lib/python2.7/json/__init__.py", line 339, in loads
    return _default_decoder.decode(s)
  File "/System/Library/Frameworks/Python.framework/Versions/2.7/lib/python2.7/json/decoder.py", line 364, in decode
    obj, end = self.raw_decode(s, idx=_w(s, 0).end())
  File "/System/Library/Frameworks/Python.framework/Versions/2.7/lib/python2.7/json/decoder.py", line 382, in raw_decode
    raise ValueError("No JSON object could be decoded")
ValueError: No JSON object could be decoded

2020-04-09 14:03:11,017 server.py [line:50] INFO loading config file...
2020-04-09 14:04:49,766 server.py [line:45] INFO loading config file...
2020-04-09 14:05:43,025 server.py [line:45] INFO loading config file...
2020-04-09 14:06:09,456 server.py [line:45] INFO loading config file...
2020-04-09 14:15:33,392 server.py [line:48] INFO loading config file...
2020-04-09 14:38:50,464 server.py [line:56] INFO loading config file...
2020-04-09 14:40:20,720 server.py [line:58] INFO loading config file...
2020-04-09 14:53:43,971 server.py [line:58] INFO loading config file...
2020-04-09 14:53:44,152 server.py [line:75] ERROR Traceback (most recent call last):
  File "/Users/brian/Desktop/FileSync2/FileSync2/server.py", line 73, in <module>
    main()
  File "/Users/brian/Desktop/FileSync2/FileSync2/server.py", line 68, in main
    server.start()
  File "/Users/brian/Desktop/FileSync2/FileSync2/server.py", line 36, in start
    zy = self.asclient.file.path2gns(path='课程/破产清算/课程资源')
  File "/Users/brian/Desktop/FileSync2/FileSync2/modules/asclient/as_file.py", line 161, in path2gns
    result = self.request(self.file_url, req_params, req_payload)
  File "/Users/brian/Desktop/FileSync2/FileSync2/modules/asclient/api_manage.py", line 36, in request
    return self.check_resp(resp)
  File "/Users/brian/Desktop/FileSync2/FileSync2/modules/asclient/api_manage.py", line 27, in check_resp
    raise APIResponseError(resp.url, result['errcode'], result['errmsg'], result['causemsg'])
APIResponseError: Request 管理对象不存在。 failed. errcode: 403024, errmsg: 管理对象不存在。, causemsg:管理对象(课程)不存在。（错误提供者：EVFS，错误值：16777729，错误位置：/var/lib/jenkins/workspace/EFAST_AS6.0/AS6.0/DataEngine/EFAST/EApp/EVFS/src/evfs/ncEVFSQueryHandler.cpp:2660）

2020-04-09 14:55:52,484 server.py [line:58] INFO loading config file...
2020-04-09 14:56:20,710 server.py [line:59] INFO loading config file...
2020-04-09 14:57:32,425 server.py [line:59] INFO loading config file...
2020-04-09 14:58:09,211 server.py [line:59] INFO loading config file...
2020-04-09 14:58:39,581 server.py [line:59] INFO loading config file...
2020-04-09 15:00:00,733 server.py [line:59] INFO loading config file...
2020-04-09 15:03:12,197 server.py [line:59] INFO loading config file...
2020-04-09 15:05:24,966 server.py [line:59] INFO loading config file...
2020-04-09 15:07:21,581 server.py [line:59] INFO loading config file...
2020-04-09 15:09:22,577 server.py [line:59] INFO loading config file...
2020-04-09 15:34:53,688 server.py [line:59] INFO loading config file...
2020-04-09 15:59:42,992 server.py [line:59] INFO loading config file...
2020-04-09 16:22:44,060 server.py [line:59] INFO loading config file...
2020-04-09 16:27:37,428 server.py [line:59] INFO loading config file...
2020-04-09 16:56:25,366 server.py [line:59] INFO loading config file...
2020-04-09 17:02:46,861 server.py [line:59] INFO loading config file...
2020-04-09 17:29:40,221 server.py [line:59] INFO loading config file...
2020-04-09 17:33:20,069 server.py [line:66] INFO loading config file...
2020-04-09 17:35:14,235 server.py [line:66] INFO loading config file...
2020-04-09 17:38:05,421 server.py [line:66] INFO loading config file...
2020-04-09 17:48:02,595 server.py [line:45] INFO loading config file...
2020-04-09 17:49:12,874 server.py [line:45] INFO loading config file...
2020-04-09 17:54:03,286 server.py [line:45] INFO loading config file...
2020-04-09 17:54:19,704 server.py [line:45] INFO loading config file...
2020-04-09 17:59:53,956 server.py [line:50] INFO loading config file...
2020-04-09 18:07:25,541 server.py [line:50] INFO loading config file...
